# Résumé des Corrections d'Imports

## Problème Identifié

L'erreur d'import suivante s'est produite :
```
ImportError: cannot import name 'InventoryNotFoundException' from 'core.exceptions' (C:\Users\DELL\Documents\GitHub\InventaireModuleWMS\core\exceptions\__init__.py). Did you mean: 'SyncInventoryNotFoundException'?
```

## Cause du Problème

Des conflits de noms d'exceptions existaient entre les différents modules d'exceptions :

1. **`InventoryNotFoundException`** était définie dans :
   - `core/exceptions/sync_exceptions.py`
   - `core/exceptions/inventory_exceptions.py`

2. **`DatabaseConnectionException`** était définie dans :
   - `core/exceptions/sync_exceptions.py`
   - `core/exceptions/inventory_exceptions.py`
   - `core/exceptions/user_exceptions.py`

3. **`DataValidationException`** était définie dans :
   - `core/exceptions/sync_exceptions.py`
   - `core/exceptions/inventory_exceptions.py`
   - `core/exceptions/user_exceptions.py`

4. **`UserNotFoundException`** était définie dans :
   - `core/exceptions/auth_exceptions.py`
   - `core/exceptions/user_exceptions.py`

5. **`AccountNotFoundException`** était définie dans :
   - `core/exceptions/inventory_exceptions.py`
   - `core/exceptions/user_exceptions.py`

## Solution Appliquée

### 1. **Nettoyage des Exceptions Dupliquées**

**Dans `core/exceptions/sync_exceptions.py` :**
- Supprimé `InventoryNotFoundException`
- Supprimé `DatabaseConnectionException`
- Supprimé `DataValidationException`

**Dans `core/exceptions/user_exceptions.py` :**
- Supprimé `UserNotFoundException` (gardée dans auth_exceptions)
- Supprimé `AccountNotFoundException` (gardée dans inventory_exceptions)
- Supprimé `DatabaseConnectionException` (gardée dans inventory_exceptions)
- Supprimé `DataValidationException` (gardée dans inventory_exceptions)

### 2. **Réorganisation Logique**

Les exceptions sont maintenant organisées logiquement :

- **`auth_exceptions.py`** : Exceptions liées à l'authentification
  - `UserNotFoundException`
  - `InvalidCredentialsException`
  - `TokenInvalidException`
  - `UserInactiveException`

- **`sync_exceptions.py`** : Exceptions liées à la synchronisation
  - `SyncDataException`
  - `UploadDataException`
  - `JobNotFoundException`
  - `AssignmentNotFoundException`
  - `CountingNotFoundException`

- **`inventory_exceptions.py`** : Exceptions liées aux inventaires et données générales
  - `InventoryNotFoundException`
  - `AccountNotFoundException`
  - `DatabaseConnectionException`
  - `DataValidationException`

- **`user_exceptions.py`** : Exceptions liées aux données utilisateur
  - `ProductNotFoundException`
  - `LocationNotFoundException`
  - `StockNotFoundException`

### 3. **Correction des Imports**

**Dans `core/exceptions/__init__.py` :**
- Supprimé les alias qui causaient la confusion
- Exposé les exceptions avec leurs noms originaux
- Évité les conflits de noms

**Dans `apps/mobile/views.py` :**
- Corrigé l'import de `InventoryNotFoundException`
- Maintenu la cohérence avec les nouveaux noms d'exceptions

## Résultat

✅ **Tous les imports fonctionnent maintenant correctement**
✅ **Plus de conflits de noms d'exceptions**
✅ **Organisation logique des exceptions par domaine**
✅ **Cohérence dans l'architecture**

## Test de Validation

Un script de test `test_imports_fix.py` a été créé pour vérifier que :
1. Toutes les exceptions peuvent être importées depuis `core.exceptions`
2. Toutes les vues mobile peuvent être importées sans erreur
3. La structure du core est cohérente

## Bonnes Pratiques Appliquées

1. **Séparation des Responsabilités** : Chaque module d'exceptions a un domaine spécifique
2. **Évitement des Conflits** : Pas de noms dupliqués entre modules
3. **Organisation Logique** : Les exceptions sont regroupées par domaine fonctionnel
4. **Cohérence** : Tous les imports utilisent les mêmes noms d'exceptions

## Impact

- ✅ Résolution de l'erreur d'import `InventoryNotFoundException`
- ✅ Amélioration de la maintenabilité du code
- ✅ Structure plus claire et organisée
- ✅ Facilité d'utilisation des exceptions dans les vues 